<?xml version="1.0" encoding="utf-8"?>
<!-- =================================================================================== -->
<!-- |    This document was autogenerated by xacro from arm.xacro                      | -->
<!-- |    EDITING THIS FILE BY HAND IS NOT RECOMMENDED                                 | -->
<!-- =================================================================================== -->
<!-- Revolute-Revolute Manipulator -->
<robot name="me604">
  <!-- <xacro:include filename="$(find arm_description)/urdf/gazebo.xacro" /> -->
  <link name="world"/>
  <joint name="fixed" type="fixed">
    <parent link="world"/>
    <child link="arm_base"/>
    <origin rpy="0 0 0" xyz="0 0 0.1"/>
  </joint>
  <link name="arm_base"/>
  <link name="link1">
    <collision>
      <origin rpy="0 0 0" xyz="0 0.025 0"/>
      <geometry>
        <box size="0.05 0.05 0.05"/>
      </geometry>
      <inertial>
        <origin rpy="0 0 0" xyz="0  0.025 0"/>
        <mass value="1"/>
        <inertia ixx="0.000416666666667" ixy="0.0" ixz="0.0" iyy="0.000416666666667" iyz="0.0" izz="0.000416666666667"/>
      </inertial>
    </collision>
    <visual>
      <origin rpy="0 0 0" xyz="0 0.025 0"/>
      <geometry>
        <box size="0.05 0.05 0.05"/>
      </geometry>
    </visual>
  </link>
  <link name="link2">
    <collision>
      <origin rpy="0 0 0" xyz="0 0.025 0"/>
      <geometry>
        <box size="0.05 0.05 0.05"/>
      </geometry>
      <inertial>
        <origin rpy="0 0 0" xyz="0  0.025 0"/>
        <mass value="1"/>
        <inertia ixx="0.000416666666667" ixy="0.0" ixz="0.0" iyy="0.000416666666667" iyz="0.0" izz="0.000416666666667"/>
      </inertial>
    </collision>
    <visual>
      <origin rpy="0 0 0" xyz="0 0.025 0"/>
      <geometry>
        <box size="0.05 0.05 0.05"/>
      </geometry>
    </visual>
  </link>
  <joint name="joint_1" type="continuous">
    <parent link="arm_base"/>
    <child link="link1"/>
    <origin rpy="0 0 0" xyz="0 0 0"/>
    <axis xyz="0 0 1"/>
    <dynamics damping="0.7"/>
  </joint>
  <joint name="joint_2" type="continuous">
    <parent link="link1"/>
    <child link="link2"/>
    <origin rpy="0 0 0" xyz="0 0 0.035"/>
    <axis xyz="0 0 1"/>
    <dynamics damping="0.7"/>
  </joint>
</robot>
